2024-03-06 18:11:38,127 - guiribot - ERROR - Exception on /get [GET]
Traceback (most recent call last):
  File "C:\Users\icjardin\anaconda3\envs\proyecto\Lib\site-packages\flask\app.py", line 1463, in wsgi_app
    response = self.full_dispatch_request()
               ^^^^^^^^^^^^^^^^^^^^^^^^^^^^
  File "C:\Users\icjardin\anaconda3\envs\proyecto\Lib\site-packages\flask\app.py", line 872, in full_dispatch_request
    rv = self.handle_user_exception(e)
         ^^^^^^^^^^^^^^^^^^^^^^^^^^^^^
  File "C:\Users\icjardin\anaconda3\envs\proyecto\Lib\site-packages\flask\app.py", line 870, in full_dispatch_request
    rv = self.dispatch_request()
         ^^^^^^^^^^^^^^^^^^^^^^^
  File "C:\Users\icjardin\anaconda3\envs\proyecto\Lib\site-packages\flask\app.py", line 855, in dispatch_request
    return self.ensure_sync(self.view_functions[rule.endpoint])(**view_args)  # type: ignore[no-any-return]
           ^^^^^^^^^^^^^^^^^^^^^^^^^^^^^^^^^^^^^^^^^^^^^^^^^^^^^^^^^^^^^^^^^
  File "C:\Users\icjardin\Desktop\TrabajoFinalSAPA_IKJB\guiribot\chatbot.py", line 86, in get_bot_response
    sf.write(nombre_fichero, speech["audio"], samplerate=speech["sampling_rate"])
  File "C:\Users\icjardin\anaconda3\envs\proyecto\Lib\site-packages\soundfile.py", line 343, in write
    with SoundFile(file, 'w', samplerate, channels,
         ^^^^^^^^^^^^^^^^^^^^^^^^^^^^^^^^^^^^^^^^^^
  File "C:\Users\icjardin\anaconda3\envs\proyecto\Lib\site-packages\soundfile.py", line 658, in __init__
    self._file = self._open(file, mode_int, closefd)
                 ^^^^^^^^^^^^^^^^^^^^^^^^^^^^^^^^^^^
  File "C:\Users\icjardin\anaconda3\envs\proyecto\Lib\site-packages\soundfile.py", line 1216, in _open
    raise LibsndfileError(err, prefix="Error opening {0!r}: ".format(self.name))
soundfile.LibsndfileError: Error opening 'app/wav/1709745098-1270108.wav': System error.
2024-03-06 18:16:05,883 - guiribot - ERROR - Exception on /get [GET]
Traceback (most recent call last):
  File "C:\Users\icjardin\anaconda3\envs\proyecto\Lib\site-packages\flask\app.py", line 1463, in wsgi_app
    response = self.full_dispatch_request()
               ^^^^^^^^^^^^^^^^^^^^^^^^^^^^
  File "C:\Users\icjardin\anaconda3\envs\proyecto\Lib\site-packages\flask\app.py", line 872, in full_dispatch_request
    rv = self.handle_user_exception(e)
         ^^^^^^^^^^^^^^^^^^^^^^^^^^^^^
  File "C:\Users\icjardin\anaconda3\envs\proyecto\Lib\site-packages\flask\app.py", line 870, in full_dispatch_request
    rv = self.dispatch_request()
         ^^^^^^^^^^^^^^^^^^^^^^^
  File "C:\Users\icjardin\anaconda3\envs\proyecto\Lib\site-packages\flask\app.py", line 855, in dispatch_request
    return self.ensure_sync(self.view_functions[rule.endpoint])(**view_args)  # type: ignore[no-any-return]
           ^^^^^^^^^^^^^^^^^^^^^^^^^^^^^^^^^^^^^^^^^^^^^^^^^^^^^^^^^^^^^^^^^
  File "C:\Users\icjardin\Desktop\TrabajoFinalSAPA_IKJB\guiribot\chatbot.py", line 86, in get_bot_response
    sf.write(nombre_fichero, speech["audio"], samplerate=speech["sampling_rate"])
  File "C:\Users\icjardin\anaconda3\envs\proyecto\Lib\site-packages\soundfile.py", line 343, in write
    with SoundFile(file, 'w', samplerate, channels,
         ^^^^^^^^^^^^^^^^^^^^^^^^^^^^^^^^^^^^^^^^^^
  File "C:\Users\icjardin\anaconda3\envs\proyecto\Lib\site-packages\soundfile.py", line 658, in __init__
    self._file = self._open(file, mode_int, closefd)
                 ^^^^^^^^^^^^^^^^^^^^^^^^^^^^^^^^^^^
  File "C:\Users\icjardin\anaconda3\envs\proyecto\Lib\site-packages\soundfile.py", line 1216, in _open
    raise LibsndfileError(err, prefix="Error opening {0!r}: ".format(self.name))
soundfile.LibsndfileError: Error opening 'app/wav/1709745365-8831232.wav': System error.
2024-03-06 18:19:48,539 - guiribot - ERROR - Exception on /get [GET]
Traceback (most recent call last):
  File "C:\Users\icjardin\anaconda3\envs\proyecto\Lib\site-packages\flask\app.py", line 1463, in wsgi_app
    response = self.full_dispatch_request()
               ^^^^^^^^^^^^^^^^^^^^^^^^^^^^
  File "C:\Users\icjardin\anaconda3\envs\proyecto\Lib\site-packages\flask\app.py", line 872, in full_dispatch_request
    rv = self.handle_user_exception(e)
         ^^^^^^^^^^^^^^^^^^^^^^^^^^^^^
  File "C:\Users\icjardin\anaconda3\envs\proyecto\Lib\site-packages\flask\app.py", line 870, in full_dispatch_request
    rv = self.dispatch_request()
         ^^^^^^^^^^^^^^^^^^^^^^^
  File "C:\Users\icjardin\anaconda3\envs\proyecto\Lib\site-packages\flask\app.py", line 855, in dispatch_request
    return self.ensure_sync(self.view_functions[rule.endpoint])(**view_args)  # type: ignore[no-any-return]
           ^^^^^^^^^^^^^^^^^^^^^^^^^^^^^^^^^^^^^^^^^^^^^^^^^^^^^^^^^^^^^^^^^
  File "C:\Users\icjardin\Desktop\TrabajoFinalSAPA_IKJB\guiribot\chatbot.py", line 86, in get_bot_response
    sf.write(nombre_fichero, speech["audio"], samplerate=speech["sampling_rate"])
  File "C:\Users\icjardin\anaconda3\envs\proyecto\Lib\site-packages\soundfile.py", line 343, in write
    with SoundFile(file, 'w', samplerate, channels,
         ^^^^^^^^^^^^^^^^^^^^^^^^^^^^^^^^^^^^^^^^^^
  File "C:\Users\icjardin\anaconda3\envs\proyecto\Lib\site-packages\soundfile.py", line 658, in __init__
    self._file = self._open(file, mode_int, closefd)
                 ^^^^^^^^^^^^^^^^^^^^^^^^^^^^^^^^^^^
  File "C:\Users\icjardin\anaconda3\envs\proyecto\Lib\site-packages\soundfile.py", line 1216, in _open
    raise LibsndfileError(err, prefix="Error opening {0!r}: ".format(self.name))
soundfile.LibsndfileError: Error opening 'app/wav/1709745588-5393934.wav': System error.
2024-03-06 18:20:29,215 - guiribot - ERROR - Exception on /get [GET]
Traceback (most recent call last):
  File "C:\Users\icjardin\anaconda3\envs\proyecto\Lib\site-packages\flask\app.py", line 1463, in wsgi_app
    response = self.full_dispatch_request()
               ^^^^^^^^^^^^^^^^^^^^^^^^^^^^
  File "C:\Users\icjardin\anaconda3\envs\proyecto\Lib\site-packages\flask\app.py", line 872, in full_dispatch_request
    rv = self.handle_user_exception(e)
         ^^^^^^^^^^^^^^^^^^^^^^^^^^^^^
  File "C:\Users\icjardin\anaconda3\envs\proyecto\Lib\site-packages\flask\app.py", line 870, in full_dispatch_request
    rv = self.dispatch_request()
         ^^^^^^^^^^^^^^^^^^^^^^^
  File "C:\Users\icjardin\anaconda3\envs\proyecto\Lib\site-packages\flask\app.py", line 855, in dispatch_request
    return self.ensure_sync(self.view_functions[rule.endpoint])(**view_args)  # type: ignore[no-any-return]
           ^^^^^^^^^^^^^^^^^^^^^^^^^^^^^^^^^^^^^^^^^^^^^^^^^^^^^^^^^^^^^^^^^
  File "C:\Users\icjardin\Desktop\TrabajoFinalSAPA_IKJB\guiribot\chatbot.py", line 86, in get_bot_response
    sf.write(nombre_fichero, speech["audio"], samplerate=speech["sampling_rate"])
  File "C:\Users\icjardin\anaconda3\envs\proyecto\Lib\site-packages\soundfile.py", line 343, in write
    with SoundFile(file, 'w', samplerate, channels,
         ^^^^^^^^^^^^^^^^^^^^^^^^^^^^^^^^^^^^^^^^^^
  File "C:\Users\icjardin\anaconda3\envs\proyecto\Lib\site-packages\soundfile.py", line 658, in __init__
    self._file = self._open(file, mode_int, closefd)
                 ^^^^^^^^^^^^^^^^^^^^^^^^^^^^^^^^^^^
  File "C:\Users\icjardin\anaconda3\envs\proyecto\Lib\site-packages\soundfile.py", line 1216, in _open
    raise LibsndfileError(err, prefix="Error opening {0!r}: ".format(self.name))
soundfile.LibsndfileError: Error opening 'app/wav/1709745629-2155108.wav': System error.
2024-03-06 18:22:34,589 - guiribot - ERROR - Error en la ruta: 404 Not Found: The requested URL was not found on the server. If you entered the URL manually please check your spelling and try again.
2024-03-06 18:24:11,177 - guiribot - ERROR - Error en la ruta: 404 Not Found: The requested URL was not found on the server. If you entered the URL manually please check your spelling and try again.
2024-03-06 18:26:10,561 - guiribot - ERROR - Error en la ruta: 404 Not Found: The requested URL was not found on the server. If you entered the URL manually please check your spelling and try again.
2024-03-06 18:28:53,623 - guiribot - ERROR - Error en la ruta: 404 Not Found: The requested URL was not found on the server. If you entered the URL manually please check your spelling and try again.
2024-03-06 18:29:29,470 - guiribot - ERROR - Error en la ruta: 404 Not Found: The requested URL was not found on the server. If you entered the URL manually please check your spelling and try again.
2024-03-06 18:31:26,380 - guiribot - ERROR - Error en la ruta: 404 Not Found: The requested URL was not found on the server. If you entered the URL manually please check your spelling and try again.
